{"trial_id": "01", "hyperparameters": {"space": [{"class_name": "Int", "config": {"name": "conv_1_filters", "default": null, "conditions": [], "min_value": 32, "max_value": 128, "step": 32, "sampling": "linear"}}, {"class_name": "Choice", "config": {"name": "conv_1_kernel_size", "default": 3, "conditions": [], "values": [3, 5], "ordered": true}}, {"class_name": "Int", "config": {"name": "conv_2_filters", "default": null, "conditions": [], "min_value": 32, "max_value": 128, "step": 32, "sampling": "linear"}}, {"class_name": "Choice", "config": {"name": "conv_2_kernel_size", "default": 3, "conditions": [], "values": [3, 5], "ordered": true}}, {"class_name": "Int", "config": {"name": "dense_units", "default": null, "conditions": [], "min_value": 64, "max_value": 256, "step": 32, "sampling": "linear"}}, {"class_name": "Float", "config": {"name": "dropout_rate", "default": 0.2, "conditions": [], "min_value": 0.2, "max_value": 0.5, "step": 0.1, "sampling": "linear"}}, {"class_name": "Float", "config": {"name": "learning_rate", "default": 0.0001, "conditions": [], "min_value": 0.0001, "max_value": 0.01, "step": null, "sampling": "log"}}], "values": {"conv_1_filters": 32, "conv_1_kernel_size": 3, "conv_2_filters": 128, "conv_2_kernel_size": 3, "dense_units": 160, "dropout_rate": 0.2, "learning_rate": 0.003373883886433183}}, "metrics": {"metrics": {}}, "score": null, "best_step": 0, "status": "FAILED", "message": "Traceback (most recent call last):\n  File \"/Users/liuyuying/opt/anaconda3/envs/tftest/lib/python3.8/site-packages/keras_tuner/src/engine/base_tuner.py\", line 274, in _try_run_and_update_trial\n    self._run_and_update_trial(trial, *fit_args, **fit_kwargs)\n  File \"/Users/liuyuying/opt/anaconda3/envs/tftest/lib/python3.8/site-packages/keras_tuner/src/engine/base_tuner.py\", line 239, in _run_and_update_trial\n    results = self.run_trial(trial, *fit_args, **fit_kwargs)\n  File \"/Users/liuyuying/opt/anaconda3/envs/tftest/lib/python3.8/site-packages/keras_tuner/src/engine/tuner.py\", line 314, in run_trial\n    obj_value = self._build_and_fit_model(trial, *args, **copied_kwargs)\n  File \"/Users/liuyuying/opt/anaconda3/envs/tftest/lib/python3.8/site-packages/keras_tuner/src/engine/tuner.py\", line 233, in _build_and_fit_model\n    results = self.hypermodel.fit(hp, model, *args, **kwargs)\n  File \"/Users/liuyuying/opt/anaconda3/envs/tftest/lib/python3.8/site-packages/keras_tuner/src/engine/hypermodel.py\", line 149, in fit\n    return model.fit(*args, **kwargs)\n  File \"/Users/liuyuying/opt/anaconda3/envs/tftest/lib/python3.8/site-packages/keras/src/utils/traceback_utils.py\", line 70, in error_handler\n    raise e.with_traceback(filtered_tb) from None\n  File \"/var/folders/4g/fzwy7zvn4n7_mt0hzjjtkfw40000gn/T/__autograph_generated_fileal1gz2l_.py\", line 15, in tf__train_function\n    retval_ = ag__.converted_call(ag__.ld(step_function), (ag__.ld(self), ag__.ld(iterator)), None, fscope)\nValueError: in user code:\n\n    File \"/Users/liuyuying/opt/anaconda3/envs/tftest/lib/python3.8/site-packages/keras/src/engine/training.py\", line 1338, in train_function  *\n        return step_function(self, iterator)\n    File \"/Users/liuyuying/opt/anaconda3/envs/tftest/lib/python3.8/site-packages/keras/src/engine/training.py\", line 1322, in step_function  **\n        outputs = model.distribute_strategy.run(run_step, args=(data,))\n    File \"/Users/liuyuying/opt/anaconda3/envs/tftest/lib/python3.8/site-packages/keras/src/engine/training.py\", line 1303, in run_step  **\n        outputs = model.train_step(data)\n    File \"/Users/liuyuying/opt/anaconda3/envs/tftest/lib/python3.8/site-packages/keras/src/engine/training.py\", line 1081, in train_step\n        loss = self.compute_loss(x, y, y_pred, sample_weight)\n    File \"/Users/liuyuying/opt/anaconda3/envs/tftest/lib/python3.8/site-packages/keras/src/engine/training.py\", line 1139, in compute_loss\n        return self.compiled_loss(\n    File \"/Users/liuyuying/opt/anaconda3/envs/tftest/lib/python3.8/site-packages/keras/src/engine/compile_utils.py\", line 265, in __call__\n        loss_value = loss_obj(y_t, y_p, sample_weight=sw)\n    File \"/Users/liuyuying/opt/anaconda3/envs/tftest/lib/python3.8/site-packages/keras/src/losses.py\", line 142, in __call__\n        losses = call_fn(y_true, y_pred)\n    File \"/Users/liuyuying/opt/anaconda3/envs/tftest/lib/python3.8/site-packages/keras/src/losses.py\", line 268, in call  **\n        return ag_fn(y_true, y_pred, **self._fn_kwargs)\n    File \"/Users/liuyuying/opt/anaconda3/envs/tftest/lib/python3.8/site-packages/keras/src/losses.py\", line 2122, in categorical_crossentropy\n        return backend.categorical_crossentropy(\n    File \"/Users/liuyuying/opt/anaconda3/envs/tftest/lib/python3.8/site-packages/keras/src/backend.py\", line 5560, in categorical_crossentropy\n        target.shape.assert_is_compatible_with(output.shape)\n\n    ValueError: Shapes (32, 1) and (32, 10) are incompatible\n\n"}